raise HTTPError(http_error_msg, response=self)


requests.exceptions.HTTPError: 404 Client Error: Not Found for url: http+docker://localhost/v1.48/containers/f9dd549642e18553a6f80aaf73f3f758ff534b27b75a633cb4d25af76dab0ef5/json




The above exception was the direct cause of the following exception:




Traceback (most recent call last):


File "/usr/local/lib/python3.13/site-packages/flask/app.py", line 1511, in wsgi_app


response = self.full_dispatch_request()


File "/usr/local/lib/python3.13/site-packages/flask/app.py", line 919, in full_dispatch_request


rv = self.handle_user_exception(e)


File "/usr/local/lib/python3.13/site-packages/flask/app.py", line 917, in full_dispatch_request


rv = self.dispatch_request()


File "/usr/local/lib/python3.13/site-packages/flask/app.py", line 902, in dispatch_request


return self.ensure_sync(self.view_functions[rule.endpoint])(**view_args) # type: ignore[no-any-return]


~~~~~~~~~~~~~~~~~~~~~~~~~~~~~~~~~~~~~~~~~~~~~~~~~~~~^^^^^^^^^^^^^


File "/app/app.py", line 54, in create_emulator


container.reload()


~~~~~~~~~~~~~~~~^^


File "/usr/local/lib/python3.13/site-packages/docker/models/resource.py", line 47, in reload


new_model = self.collection.get(self.id)


File "/usr/local/lib/python3.13/site-packages/docker/models/containers.py", line 954, in get


resp = self.client.api.inspect_container(container_id)


File "/usr/local/lib/python3.13/site-packages/docker/utils/decorators.py", line 19, in wrapped


return f(self, resource_id, *args, **kwargs)


File "/usr/local/lib/python3.13/site-packages/docker/api/container.py", line 793, in inspect_container


return self._result(


~~~~~~~~~~~~^


self._get(self._url("/containers/{0}/json", container)), True


^^^^^^^^^^^^^^^^^^^^^^^^^^^^^^^^^^^^^^^^^^^^^^^^^^^^^^^^^^^^^


)


^


File "/usr/local/lib/python3.13/site-packages/docker/api/client.py", line 281, in _result


self._raise_for_status(response)


~~~~~~~~~~~~~~~~~~~~~~^^^^^^^^^^


File "/usr/local/lib/python3.13/site-packages/docker/api/client.py", line 277, in _raise_for_status


raise create_api_error_from_http_exception(e) from e


~~~~~~~~~~~~~~~~~~~~~~~~~~~~~~~~~~~~^^^


File "/usr/local/lib/python3.13/site-packages/docker/errors.py", line 39, in create_api_error_from_http_exception


raise cls(e, response=response, explanation=explanation) from e


docker.errors.NotFound: 404 Client Error for http+docker://localhost/v1.48/containers/f9dd549642e18553a6f80aaf73f3f758ff534b27b75a633cb4d25af76dab0ef5/json: Not Found ("No such container: f9dd549642e18553a6f80aaf73f3f758ff534b27b75a633cb4d25af76dab0ef5")


172.18.0.1 - - [23/Apr/2025 12:19:26] "POST /emulators HTTP/1.1" 500 -


172.18.0.1 - - [23/Apr/2025 12:19:35] "GET /healthcheck?fix=true HTTP/1.1" 200 -


172.18.0.1 - - [23/Apr/2025 12:19:35] "GET /healthcheck HTTP/1.1" 200 -



